Workbook

Sheet Read me
A1: Nexus phase 1: sprint sheet
A3: Scope | B3: Only what comes from DATOMS, Microsoft Entra ID (sign-in and access) and the map. Items from the brief whose source is not known yet (tracked materials, weather, gallery and drone library, manpower and HSE, live CCTV, project details DATOMS lacks) are on the Future tab and are added once their source is confirmed.
A4: Team | B4: Today: 2 people (you on backend, your colleague on frontend). More people will be hired: each task names the Role that owns it once hired, and 'Now done by' shows who does it until then. See the Hiring tab.
A5: Sprint length | B5: 2 weeks (assumption: no deadline set). Change the Weeks column on Sprint plan if you pick another length.
A6: Capacity | B6: About 8 working days per person per sprint, leaving room for meetings, reviews and fixes.
A7: Total | B7: 11 sprints, about 22 weeks, if the DATOMS API documentation arrives by sprint 2.
A8: How to use | B8: Work sprint by sprint. On the Backlog tab, filter Sprint (e.g. S0), then Week (W1, W2). Each task has numbered Steps, the Output that should exist when done, and an Acceptance check. Update Status (yellow cells); Sprint plan totals and % done update by themselves.
A9: When someone joins | B9: Change 'Now done by' to their name for their Role's tasks. With more people, later sprints can run in parallel and the 26 weeks shrinks.
A10: Status values | B10: Not started · In progress · Blocked · Done. A Blocked row turns red; a Done row turns green.
A11: External blocker | B11: Anything outside your control (DATOMS answers, access, pilot users). If it isn't ready, swap in a task from a later sprint that has none.
A12: Requirement | B12: Where the task comes from: 'Sheet: ...' = structure sheet, 'Brief: ...' = project brief, 'Innovo: ...' = Innovo's answers.

Sheet Sprint plan
A1: Sprint | B1: Name | C1: Weeks | D1: Goal (demo at the end) | E1: External dependency | F1: Tasks | G1: You (backend) days | H1: Colleague (frontend) days | I1: Shared days | J1: Total days | K1: Done days | L1: % done
A2: S0 | B2: Setup + map decision | C2: 1–2 | D2: Repos, Azure dev environment, Microsoft sign-in skeleton, design tokens, ArcGIS map wrapper skeleton | E2: Azure and Entra access; map decision | F2: =COUNTIF(Backlog!$B$2:$B$77,A2) | G2: =SUMIFS(Backlog!$M$2:$M$77,Backlog!$B$2:$B$77,A2,Backlog!$I$2:$I$77,"You (backend)") | H2: =SUMIFS(Backlog!$M$2:$M$77,Backlog!$B$2:$B$77,A2,Backlog!$I$2:$I$77,"Colleague (frontend)") | I2: =SUMIFS(Backlog!$M$2:$M$77,Backlog!$B$2:$B$77,A2,Backlog!$I$2:$I$77,"Both") | J2: =SUMIF(Backlog!$B$2:$B$77,A2,Backlog!$M$2:$M$77) | K2: =SUMIFS(Backlog!$M$2:$M$77,Backlog!$B$2:$B$77,A2,Backlog!$N$2:$N$77,"Done") | L2: =IF(J2=0,0,K2/J2)
A3: S1 | B3: Foundation | C3: 3–4 | D3: Data model, permissions in the API, app shell, responsive layout | E3: Nothing | F3: =COUNTIF(Backlog!$B$2:$B$77,A3) | G3: =SUMIFS(Backlog!$M$2:$M$77,Backlog!$B$2:$B$77,A3,Backlog!$I$2:$I$77,"You (backend)") | H3: =SUMIFS(Backlog!$M$2:$M$77,Backlog!$B$2:$B$77,A3,Backlog!$I$2:$I$77,"Colleague (frontend)") | I3: =SUMIFS(Backlog!$M$2:$M$77,Backlog!$B$2:$B$77,A3,Backlog!$I$2:$I$77,"Both") | J3: =SUMIF(Backlog!$B$2:$B$77,A3,Backlog!$M$2:$M$77) | K3: =SUMIFS(Backlog!$M$2:$M$77,Backlog!$B$2:$B$77,A3,Backlog!$N$2:$N$77,"Done") | L3: =IF(J3=0,0,K3/J3)
A4: S2 | B4: Portfolio map + access | C4: 5–6 | D4: Top-level map of all DATOMS sites; DATOMS client; users and roles API | E4: DATOMS sample bulk response + bulk field list (Q21, Q22) | F4: =COUNTIF(Backlog!$B$2:$B$77,A4) | G4: =SUMIFS(Backlog!$M$2:$M$77,Backlog!$B$2:$B$77,A4,Backlog!$I$2:$I$77,"You (backend)") | H4: =SUMIFS(Backlog!$M$2:$M$77,Backlog!$B$2:$B$77,A4,Backlog!$I$2:$I$77,"Colleague (frontend)") | I4: =SUMIFS(Backlog!$M$2:$M$77,Backlog!$B$2:$B$77,A4,Backlog!$I$2:$I$77,"Both") | J4: =SUMIF(Backlog!$B$2:$B$77,A4,Backlog!$M$2:$M$77) | K4: =SUMIFS(Backlog!$M$2:$M$77,Backlog!$B$2:$B$77,A4,Backlog!$N$2:$N$77,"Done") | L4: =IF(J4=0,0,K4/J4)
A5: S3 | B5: DATOMS sync + admin | C5: 7–8 | D5: Live DATOMS data flowing; device linking, sync health, users and roles screens | E5: DATOMS sample + field list (Q21, Q22) + key | F5: =COUNTIF(Backlog!$B$2:$B$77,A5) | G5: =SUMIFS(Backlog!$M$2:$M$77,Backlog!$B$2:$B$77,A5,Backlog!$I$2:$I$77,"You (backend)") | H5: =SUMIFS(Backlog!$M$2:$M$77,Backlog!$B$2:$B$77,A5,Backlog!$I$2:$I$77,"Colleague (frontend)") | I5: =SUMIFS(Backlog!$M$2:$M$77,Backlog!$B$2:$B$77,A5,Backlog!$I$2:$I$77,"Both") | J5: =SUMIF(Backlog!$B$2:$B$77,A5,Backlog!$M$2:$M$77) | K5: =SUMIFS(Backlog!$M$2:$M$77,Backlog!$B$2:$B$77,A5,Backlog!$N$2:$N$77,"Done") | L5: =IF(J5=0,0,K5/J5)
A6: S4 | B6: Project page | C6: 9–10 | D6: Level 1 page with live asset pins and equipment / energy boxes | E6: Bulk field names for location + status (Q22) | F6: =COUNTIF(Backlog!$B$2:$B$77,A6) | G6: =SUMIFS(Backlog!$M$2:$M$77,Backlog!$B$2:$B$77,A6,Backlog!$I$2:$I$77,"You (backend)") | H6: =SUMIFS(Backlog!$M$2:$M$77,Backlog!$B$2:$B$77,A6,Backlog!$I$2:$I$77,"Colleague (frontend)") | I6: =SUMIFS(Backlog!$M$2:$M$77,Backlog!$B$2:$B$77,A6,Backlog!$I$2:$I$77,"Both") | J6: =SUMIF(Backlog!$B$2:$B$77,A6,Backlog!$M$2:$M$77) | K6: =SUMIFS(Backlog!$M$2:$M$77,Backlog!$B$2:$B$77,A6,Backlog!$N$2:$N$77,"Done") | L6: =IF(J6=0,0,K6/J6)
A7: S5 | B7: Energy | C7: 11–12 | D7: Info box 3 and energy detail page; load-test harness | E7: Whether DATOMS has site totals and ownership (Q3); field names (Q22) | F7: =COUNTIF(Backlog!$B$2:$B$77,A7) | G7: =SUMIFS(Backlog!$M$2:$M$77,Backlog!$B$2:$B$77,A7,Backlog!$I$2:$I$77,"You (backend)") | H7: =SUMIFS(Backlog!$M$2:$M$77,Backlog!$B$2:$B$77,A7,Backlog!$I$2:$I$77,"Colleague (frontend)") | I7: =SUMIFS(Backlog!$M$2:$M$77,Backlog!$B$2:$B$77,A7,Backlog!$I$2:$I$77,"Both") | J7: =SUMIF(Backlog!$B$2:$B$77,A7,Backlog!$M$2:$M$77) | K7: =SUMIFS(Backlog!$M$2:$M$77,Backlog!$B$2:$B$77,A7,Backlog!$N$2:$N$77,"Done") | L7: =IF(J7=0,0,K7/J7)
A8: S6 | B8: Equipment + notifications | C8: 13–14 | D8: Info box 2, equipment detail, device card, DATOMS notifications | E8: Alert field names in the bulk response (Q22) | F8: =COUNTIF(Backlog!$B$2:$B$77,A8) | G8: =SUMIFS(Backlog!$M$2:$M$77,Backlog!$B$2:$B$77,A8,Backlog!$I$2:$I$77,"You (backend)") | H8: =SUMIFS(Backlog!$M$2:$M$77,Backlog!$B$2:$B$77,A8,Backlog!$I$2:$I$77,"Colleague (frontend)") | I8: =SUMIFS(Backlog!$M$2:$M$77,Backlog!$B$2:$B$77,A8,Backlog!$I$2:$I$77,"Both") | J8: =SUMIF(Backlog!$B$2:$B$77,A8,Backlog!$M$2:$M$77) | K8: =SUMIFS(Backlog!$M$2:$M$77,Backlog!$B$2:$B$77,A8,Backlog!$N$2:$N$77,"Done") | L8: =IF(J8=0,0,K8/J8)
A9: S7 | B9: Explorer + hardening | C9: 15–16 | D9: All DATOMS data explorer, security hardening, production environment, mobile polish | E9: Nothing | F9: =COUNTIF(Backlog!$B$2:$B$77,A9) | G9: =SUMIFS(Backlog!$M$2:$M$77,Backlog!$B$2:$B$77,A9,Backlog!$I$2:$I$77,"You (backend)") | H9: =SUMIFS(Backlog!$M$2:$M$77,Backlog!$B$2:$B$77,A9,Backlog!$I$2:$I$77,"Colleague (frontend)") | I9: =SUMIFS(Backlog!$M$2:$M$77,Backlog!$B$2:$B$77,A9,Backlog!$I$2:$I$77,"Both") | J9: =SUMIF(Backlog!$B$2:$B$77,A9,Backlog!$M$2:$M$77) | K9: =SUMIFS(Backlog!$M$2:$M$77,Backlog!$B$2:$B$77,A9,Backlog!$N$2:$N$77,"Done") | L9: =IF(J9=0,0,K9/J9)
A10: S8 | B10: Load and security | C10: 17–18 | D10: Load test at 100+ sites, backups and alerts, penetration test, user guide | E10: Pen-test slot | F10: =COUNTIF(Backlog!$B$2:$B$77,A10) | G10: =SUMIFS(Backlog!$M$2:$M$77,Backlog!$B$2:$B$77,A10,Backlog!$I$2:$I$77,"You (backend)") | H10: =SUMIFS(Backlog!$M$2:$M$77,Backlog!$B$2:$B$77,A10,Backlog!$I$2:$I$77,"Colleague (frontend)") | I10: =SUMIFS(Backlog!$M$2:$M$77,Backlog!$B$2:$B$77,A10,Backlog!$I$2:$I$77,"Both") | J10: =SUMIF(Backlog!$B$2:$B$77,A10,Backlog!$M$2:$M$77) | K10: =SUMIFS(Backlog!$M$2:$M$77,Backlog!$B$2:$B$77,A10,Backlog!$N$2:$N$77,"Done") | L10: =IF(J10=0,0,K10/J10)
A11: S9 | B11: Pilot (GHAFWOODS) | C11: 19–20 | D11: Testing with pilot users, fixes, runbook | E11: Pilot users | F11: =COUNTIF(Backlog!$B$2:$B$77,A11) | G11: =SUMIFS(Backlog!$M$2:$M$77,Backlog!$B$2:$B$77,A11,Backlog!$I$2:$I$77,"You (backend)") | H11: =SUMIFS(Backlog!$M$2:$M$77,Backlog!$B$2:$B$77,A11,Backlog!$I$2:$I$77,"Colleague (frontend)") | I11: =SUMIFS(Backlog!$M$2:$M$77,Backlog!$B$2:$B$77,A11,Backlog!$I$2:$I$77,"Both") | J11: =SUMIF(Backlog!$B$2:$B$77,A11,Backlog!$M$2:$M$77) | K11: =SUMIFS(Backlog!$M$2:$M$77,Backlog!$B$2:$B$77,A11,Backlog!$N$2:$N$77,"Done") | L11: =IF(J11=0,0,K11/J11)
A12: S10 | B12: Rollout | C12: 21–22 | D12: All DATOMS sites live, onboarding, plan the next scope | E12: Nothing | F12: =COUNTIF(Backlog!$B$2:$B$77,A12) | G12: =SUMIFS(Backlog!$M$2:$M$77,Backlog!$B$2:$B$77,A12,Backlog!$I$2:$I$77,"You (backend)") | H12: =SUMIFS(Backlog!$M$2:$M$77,Backlog!$B$2:$B$77,A12,Backlog!$I$2:$I$77,"Colleague (frontend)") | I12: =SUMIFS(Backlog!$M$2:$M$77,Backlog!$B$2:$B$77,A12,Backlog!$I$2:$I$77,"Both") | J12: =SUMIF(Backlog!$B$2:$B$77,A12,Backlog!$M$2:$M$77) | K12: =SUMIFS(Backlog!$M$2:$M$77,Backlog!$B$2:$B$77,A12,Backlog!$N$2:$N$77,"Done") | L12: =IF(J12=0,0,K12/J12)
A13: Total | F13: =SUM(F2:F12) | G13: =SUM(G2:G12) | H13: =SUM(H2:H12) | I13: =SUM(I2:I12) | J13: =SUM(J2:J12) | K13: =SUM(K2:K12) | L13: =IF(J13=0,0,K13/J13)
A15: Capacity check: Backend days and Frontend days per sprint should stay at or under about 8 (2-week sprint, 1 person each, plus shared days).

Sheet Hiring
A1: Hiring plan: who joins when, and what they take over
A3: Order | B3: Role | C3: Join by | D3: Takes over from | E3: Tasks | F3: Days | G3: Why at this point
A4: 1 | B4: DevOps engineer | C4: S0 | D4: You (backend) | E4: =COUNTIF(Backlog!$H$2:$H$77,B4) | F4: =SUMIF(Backlog!$H$2:$H$77,B4,Backlog!$M$2:$M$77) | G4: Azure environments, pipelines and security are set up right from day one
A5: 2 | B5: UI/UX designer | C5: S0 | D5: Colleague (frontend) | E5: =COUNTIF(Backlog!$H$2:$H$77,B5) | F5: =SUMIF(Backlog!$H$2:$H$77,B5,Backlog!$M$2:$M$77) | G5: Design system and screens are ready before the frontend builds them
A6: 3 | B6: Data / integration engineer | C6: S2 | D6: You (backend) | E6: =COUNTIF(Backlog!$H$2:$H$77,B6) | F6: =SUMIF(Backlog!$H$2:$H$77,B6,Backlog!$M$2:$M$77) | G6: DATOMS sync starts in S3; frees you for APIs
A7: 4 | B7: Backend developer | C7: S3 | D7: You (backend) | E7: =COUNTIF(Backlog!$H$2:$H$77,B7) | F7: =SUMIF(Backlog!$H$2:$H$77,B7,Backlog!$M$2:$M$77) | G7: Second backend developer lets S6–S9 run in parallel
A8: 5 | B8: Frontend developer | C8: S3 | D8: Colleague (frontend) | E8: =COUNTIF(Backlog!$H$2:$H$77,B8) | F8: =SUMIF(Backlog!$H$2:$H$77,B8,Backlog!$M$2:$M$77) | G8: Second frontend developer lets screens run in parallel
A9: 6 | B9: QA engineer | C9: S4 | D9: You (backend) | E9: =COUNTIF(Backlog!$H$2:$H$77,B9) | F9: =SUMIF(Backlog!$H$2:$H$77,B9,Backlog!$M$2:$M$77) | G9: Testing grows with the number of screens; owns load and permission tests
A10: 7 | B10: Product owner | C10: S4 | D10: Both | E10: =COUNTIF(Backlog!$H$2:$H$77,B10) | F10: =SUMIF(Backlog!$H$2:$H$77,B10,Backlog!$M$2:$M$77) | G10: Runs pilot, user guide, onboarding and phase 2 priorities
A11: 8 | B11: Security engineer | C11: S8 | D11: You (backend) | E11: =COUNTIF(Backlog!$H$2:$H$77,B11) | F11: =SUMIF(Backlog!$H$2:$H$77,B11,Backlog!$M$2:$M$77) | G11: Part-time: penetration test before the pilot
B12: You (backend) keep: Backend developer tasks
B13: Colleague keeps: Frontend developer tasks
B14: Roles follow the team in the Build plan tab. Join dates are suggestions; hire earlier to finish sooner.

Sheet Backlog
A1: ID | B1: Sprint | C1: Week | D1: Work package | E1: Task | F1: Steps (how to do it) | G1: Output when done | H1: Role (owner when hired) | I1: Now done by | J1: Requirement | K1: Depends on | L1: External blocker | M1: Estimate (days) | N1: Status | O1: Acceptance check
A2: S0-01 | B2: S0 | C2: W1 | D2: Setup | E2: Monorepo: apps/web, apps/api, apps/worker, packages/shared (types). Branching and review rules | F2: 1. Create the Git repository (GitHub or Azure DevOps). 2. Set up folders: apps/web, apps/api, apps/worker, packages/shared. 3. Add a root README with how to run everything. 4. Agree rules: main branch protected, every change via pull request reviewed by the other person. | G2: Repo both of you can clone and run | H2: Backend developer | I2: You (backend) | J2: Foundation | M2: 1 | N2: Not started | O2: Both devs clone, build and run all apps locally with one command
A3: S0-02 | B3: S0 | C3: W1 | D3: Setup | E3: Azure dev environment as code (Bicep): Container Apps, PostgreSQL Flexible Server 16, Blob Storage, Key Vault, Web PubSub, Application Insights | F3: 1. Create a resource group in Azure UAE North for 'nexus-dev'. 2. Write Bicep files for: PostgreSQL Flexible Server 16 (no TimescaleDB; see docs/adr/0003), Blob Storage, Key Vault, Web PubSub, Container Apps environment, Application Insights. 3. Deploy with one command and check each resource exists. 4. Store the database password in Key Vault, not in code. | G3: Working dev environment in Azure, built from code | H3: DevOps engineer | I3: You (backend) | J3: Foundation | L3: Azure subscription access | M3: 3 | N3: Not started | O3: Environment created from code in one run; no secrets in the repo
A4: S0-03 | B4: S0 | C4: W2 | D4: Setup | E4: CI/CD pipelines for API and worker (build, test, deploy to dev) | F4: 1. Create a pipeline that runs on every pull request: install, lint, test. 2. On merge to main: build Docker images for api and worker, push to Azure Container Registry, deploy to Container Apps (dev). 3. Test by merging a small change and seeing it live. | G4: Merge to main = deployed to dev | H4: DevOps engineer | I4: You (backend) | J4: Foundation | K4: S0-02 | M4: 2 | N4: Not started | O4: Merge to main deploys to dev automatically
A5: S0-04 | B5: S0 | C5: W1 | D5: Setup | E5: Entra ID app registrations (API + web app), Nexus security groups, app-assigned groups claim | F5: 1. In Entra ID, register two apps: 'Nexus API' and 'Nexus Web'. 2. Create the Nexus security groups (docs/08 section 1; e.g. Nexus-Admins). Roles are mapped from groups in the Nexus database (docs/08 section 3), not defined as Entra app roles. The final role list is Q17. 3. On Nexus API, set the groups claim to 'Groups assigned to the application' (ADR 0008). Assign the Nexus groups to the enterprise app; users must be direct members. No Graph permission or secret. 4. Turn on 'assignment required' so only group members can sign in. 5. Share client IDs with the frontend. | G5: Sign-in apps and groups ready; test users in each group | H5: Backend developer | I5: You (backend) | J5: Innovo: permissions | L5: Entra admin consent; Entra ID P1 licence and setup confirmed by Innovo IT (Q16) | M5: 1 | N5: Not started | O5: Test users in each group get a token whose groups claim contains only their app-assigned Nexus group(s)
A6: S0-05 | B6: S0 | C6: W1 | D6: Setup | E6: React + TypeScript app shell (Vite), routing, linting | F6: 1. Create the React + TypeScript app with Vite in apps/web. 2. Add routing with empty pages: Portfolio, Project, Admin. 3. Add ESLint and Prettier. 4. Run locally. | G6: Empty app with page routes | H6: Frontend developer | I6: Colleague (frontend) | J6: Foundation | K6: S0-01 | M6: 2 | N6: Not started | O6: App runs locally and in dev
A7: S0-06 | B7: S0 | C7: W1–W2 | D7: Setup | E7: Design tokens and base components from the brief mockups (colours, type, cards, tags, tables) | F7: 1. From the brief mockups, list colours, fonts, spacing, corner radius. 2. Create them as design tokens (CSS variables). 3. Build base components: button, card, info box, tag (RES, HOSP...), table, side panel, tabs. 4. Make a 'components' page showing them all. | G7: Reusable UI building blocks matching the mockups | H7: UI/UX designer | I7: Colleague (frontend) | J7: Brief: platform experience | M7: 3 | N7: Not started | O7: Component page shows every base component on desktop and mobile
A8: S0-07 | B8: S0 | C8: W2 | D8: Setup | E8: CI/CD to Azure Static Web Apps | F8: 1. Create Azure Static Web App for dev. 2. Add a pipeline: on merge to main, build and deploy apps/web. 3. Check the dev URL works. | G8: Web app auto-deploys to dev | H8: DevOps engineer | I8: You (backend) | J8: Foundation | K8: S0-05 | M8: 1 | N8: Not started | O8: Merge to main deploys web app to dev
A9: S0-08 | B9: S0 | C9: W2 | D9: Setup | E9: Microsoft sign-in skeleton (MSAL) | F9: 1. Install MSAL React. 2. Use the 'Nexus Web' client ID from S0-04. 3. Sign-in button redirects to Microsoft; after sign-in show the user's name. 4. Test with a user outside the Nexus groups: they must be refused. | G9: Users sign in with their Innovo Microsoft account | H9: Frontend developer | I9: Colleague (frontend) | J9: Innovo: permissions | K9: S0-04 | M9: 1 | N9: Not started | O9: User signs in with Innovo account; others are refused
A10: S0-09 | B10: S0 | C10: W1 | D10: Map | E10: ArcGIS map setup (provider decided: Esri ArcGIS, ADR 0002): account and API key, MapView wrapper skeleton with the ArcGIS adapter | F10: 1. Ask Innovo IT whether Innovo has an ArcGIS Online / Enterprise organisation (open question Q4). 2. Create the ArcGIS API key (basemaps + elevation), restrict it by referrer to the Nexus domains, store it in Key Vault. 3. Serve the key to the web app through /v1/config (stub until the API exists). 4. Build components/map/types.ts, MapView.tsx and the arcgis/ adapter: lazy-loaded @arcgis/core, a UAE map with 10 sample markers, 2D / satellite / 3D switch. 5. Add the lint rule that blocks @arcgis imports outside components/map. | G10: ArcGIS key in Key Vault; MapView wrapper with ArcGIS adapter showing a UAE map in 2D, satellite and 3D; ready for S2 | H10: Frontend developer | I10: Colleague (frontend) | J10: Brief: interactive map; Sheet: Top level | L10: ArcGIS account / licence (Q4) | M10: 3 | N10: Not started | O10: UAE map renders in 2D, satellite and 3D through <MapView>; no @arcgis import outside components/map; key not in the repo
A11: S1-01 | B11: S1 | C11: W1 | D11: Foundation | E11: Core data model and migrations from db/schema.sql: project, building, level, zone, asset type, asset, parameter dictionary, latest + raw packets (daily partitions), rollups, status, location, events, access, audit | F11: 1. Use Kysely + plain SQL migrations (node-pg-migrate), per docs/04-tech-stack.md. 2. Turn db/schema.sql into migration 0001_init.sql (up + down); add db/roles.sql grants. 3. Raw telemetry is telemetry.packet: one jsonb row per asset packet, daily partitions (no TimescaleDB). 4. Every asset has project_id and optional building/level/zone ids (what BIM links to later). 5. Add pnpm db:migrate / db:check / db:seed; run the 100-site seed and record query timings. 6. From the S1-02 security review (L3, accepted for now): when roles, project scope or active status change, clear the access cache on every API instance (Postgres LISTEN/NOTIFY or a per-user access version), check is_active on a cache hit, and never cache a load that started before the change. | G11: Database structure in place | H11: Backend developer | I11: You (backend) | J11: Foundation (BIM-ready) | K11: S0-02 | M11: 3 | N11: Not started | O11: Migrations run clean; every asset links to project and optional zone
A12: S1-02 | B12: S1 | C12: W1–W2 | D12: Foundation | E12: Auth in API: token validation, role guards, project-scope filter on every query | F12: 1. Add token validation in NestJS for Entra ID tokens. 2. Read the user's roles from the token. 3. Add a guard that blocks endpoints by role. 4. Add a project-scope filter: every query only returns projects the user is assigned to (unless role = all projects). 5. Write tests: user A must never see project B. | G12: Every API call is permission-checked | H12: Backend developer | I12: You (backend) | J12: Innovo: permissions | K12: S0-04 | M12: 3 | N12: Not started | O12: Automated test: a user never receives a project outside their scope
A13: S1-03 | B13: S1 | C13: W2 | D13: Foundation | E13: OpenAPI contract published; typed client generated for the web app | F13: 1. Turn on NestJS Swagger/OpenAPI generation. 2. Publish the spec at /api/docs on dev. 3. Generate a TypeScript client into packages/shared. 4. Show the frontend how to use it. | G13: Shared API contract the frontend codes against | H13: Backend developer | I13: You (backend) | J13: Foundation | M13: 1 | N13: Not started | O13: Frontend imports generated client; build fails on contract mismatch
A14: S1-04 | B14: S1 | C14: W2 | D14: Foundation | E14: Audit log: sign-ins, data exports, settings changes | F14: 1. Create an audit service in the API. 2. Log sign-ins, settings changes, permission changes, exports: who, what, when. 3. Add an admin-only endpoint to read the log. | G14: Audit log recording key actions | H14: Backend developer | I14: You (backend) | J14: Innovo: security | M14: 1 | N14: Not started | O14: Each action writes user, time and action
A15: S1-05 | B15: S1 | C15: W1 | D15: Foundation | E15: App shell: header, global search box, notifications bell, user menu | F15: 1. Build the top header from the mockup: Innovo/Nexus logo, search box, UAE label, bell, user avatar. 2. User menu shows name and sign-out. 3. Search and bell are placeholders for now. | G15: App frame visible on every page | H15: Frontend developer | I15: Colleague (frontend) | J15: Brief mockups | K15: S0-06 | M15: 2 | N15: Not started | O15: Matches mockup header on desktop
A16: S1-06 | B16: S1 | C16: W1–W2 | D16: Foundation | E16: Responsive layout for desktop, tablet and mobile | F16: 1. Desktop: list panel left, map centre, details panel right (as mockup). 2. Tablet: list panel collapses to a button. 3. Mobile: map full width, panels open as bottom drawers. 4. Test at 1440, 1024 and 390 px wide. | G16: Layout works on desktop, tablet and phone | H16: Frontend developer | I16: Colleague (frontend) | J16: Innovo: devices | M16: 2 | N16: Not started | O16: No horizontal scroll at 390 px; side panel becomes a drawer on mobile
A17: S1-07 | B17: S1 | C17: W2 | D17: Foundation | E17: Loading, error and empty states using the generated API client | F17: 1. Connect the generated API client from S1-03. 2. Make shared components for: loading spinner, 'no data yet', error with retry. 3. Use them on every page. | G17: Consistent loading, empty and error states | H17: Frontend developer | I17: Colleague (frontend) | J17: Foundation | K17: S1-03 | M17: 2 | N17: Not started | O17: Every page shows a clear state when data is loading, missing or failed
A18: S1-08 | B18: S1 | C18: W2 | D18: Foundation | E18: Navigation filtered by role | F18: 1. Read the user's roles from the sign-in token. 2. Hide Admin menu for non-admins. 3. Hide pages the role cannot open. | G18: Menus match the user's role | H18: Frontend developer | I18: Colleague (frontend) | J18: Innovo: permissions | K18: S1-02 | M18: 1 | N18: Not started | O18: Admin console hidden for non-admins
A19: S1-09 | B19: S1 | C19: W2 | D19: Foundation | E19: API baseline protections: helmet, CORS for Nexus web origins only, per-user rate limit, request size limit, Swagger UI off in prod | F19: 1. Add helmet (@fastify/helmet) so every API response carries secure headers. 2. Enable CORS only for the Nexus web origins, read from config per environment (no wildcard); add the variable to .env.example and docs/04. 3. Add a per-user rate limit keyed on the Entra oid (by IP before sign-in); over the limit gives 429 problem+json with Retry-After; limits come from config. 4. Set a request body size limit (Fastify bodyLimit) from config; larger bodies get 413. 5. Serve Swagger UI only when APP_ENV is not prod. 6. Update docs/08 §6 and docs/10. Needed before S2-01 (security review of S1-02, item I6). | G19: The API refuses other origins, oversized bodies and excessive requests, and sends secure headers | H19: Backend developer | I19: You (backend) | J19: Innovo: security | K19: S1-02 | M19: 1 | N19: Not started | O19: Automated tests: a non-Nexus origin gets no CORS headers; a user over the limit gets 429 with Retry-After; an oversized body gets 413; secure headers on every response; Swagger UI gives 404 when APP_ENV=prod
A20: S2-01 | B20: S2 | C20: W1 | D20: Portfolio map | E20: Projects API: list, filter (status, type, district), search, scoped to user | F20: 1. Create GET /projects with filters: status, type, district, search text. 2. Apply the project-scope filter from S1-02. 3. Return the fields DATOMS provides for each site (name, location, type, status). 4. Add seed data for 5 sample sites so the frontend can work before DATOMS is connected. | G20: Projects list endpoint the map uses | H20: Backend developer | I20: You (backend) | J20: Sheet: Top level | K20: S1-02, S1-09 | M20: 2 | N20: Not started | O20: Returns only the user's projects; search under 300 ms
A21: S2-02 | B21: S2 | C21: W2 | D21: DATOMS connector | E21: DATOMS API client: bulk endpoint, paging, retries, rate-limit and credit handling | F21: 1. Read the v4 PDF, plus the DATOMS sample bulk response (Q21) and bulk field list (Q22) once received. 2. Build packages/datoms-client: list assets (catalogue) and the bulk endpoint (fleet and id mode) as the ONLY telemetry source (ADR 0010). data/latest is for CLI checks only. 3. Put ALL field mapping in src/mapping.ts. Until the sample arrives, build against the v4 PDF shape. Save the sample to fixtures/ with tokens removed. 4. Handle paging, 422 halving (with the learned page size), retries, rate limits, and the credit budget with budget.max_share (ADR 0005). 5. Test against GHAFWOODS on dev using fixtures or a small id-mode subset (never the full fleet from dev). | G21: Code that can talk to DATOMS | H21: Data / integration engineer | I21: You (backend) | J21: Brief: energy, crane utilisation | L21: DATOMS sample bulk response (Q21) + bulk field list (Q22) + read-only key. Needed before this task starts; they do not block S0 or S1. | M21: 3 | N21: Not started | O21: Client reads the GHAFWOODS demo fleet (generators and tower cranes) through the bulk endpoint in dev; DATOMS field names exist only in src/mapping.ts
A22: S2-03 | B22: S2 | C22: W1–W2 | D22: Portfolio map | E22: Portfolio map (chosen provider, through the map wrapper): one pin per DATOMS site, coloured Active green, Central Store blue, Finished grey, In bid yellow where DATOMS gives the status | F22: 1. Use the MapView wrapper with the ArcGIS adapter from S0-09. 2. Show a UAE map. 3. Call GET /projects and draw one pin per project. 4. Colour pins: Active green, Central Store blue, Finished grey, In bid yellow (structure sheet). 5. Click a pin = zoom to that project. | G22: Top-level portfolio map | H22: Frontend developer | I22: Colleague (frontend) | J22: Sheet: Top level | K22: S0-09 | M22: 3 | N22: Not started | O22: All projects shown; colours match the sheet; click zooms to project
A23: S2-04 | B23: S2 | C23: W2 | D23: Portfolio map | E23: Project list panel and summary tiles (projects, districts) | F23: 1. Left panel: list of sites with the details DATOMS provides (name, location, type, status). 2. Two summary tiles at the top: number of projects, number of districts. 3. Click a project in the list = same as clicking its pin. | G23: Project list beside the map | H23: Frontend developer | I23: Colleague (frontend) | J23: Brief mockups | K23: S2-01 | M23: 2 | N23: Not started | O23: List matches mockup: name, district, type tag, client, consultant, PM
A24: S2-05 | B24: S2 | C24: W2 | D24: Portfolio map | E24: Search and filters | F24: 1. Search box filters the list and pins by name. 2. Filter chips: status, type, district. 3. Filters call GET /projects with parameters. | G24: Users can find any project fast | H24: Frontend developer | I24: Colleague (frontend) | J24: Brief mockups | K24: S2-01 | M24: 2 | N24: Not started | O24: Filter by status, type, district; search by name
A25: S2-06 | B25: S2 | C25: W2 | D25: Admin console | E25: Users and roles API: group-to-role mapping, project assignment, extra permissions | F25: 1. Endpoint listing Entra groups and their Nexus role. 2. Endpoints to assign users to projects. Keep room for extra permissions that later modules will need. 3. Admin only; every change goes to the audit log. | G25: Backend for managing access | H25: Backend developer | I25: You (backend) | J25: Innovo: permissions | K25: S1-02 | M25: 2 | N25: Not started | O25: Changes take effect on next request
A26: S3-01 | B26: S3 | C26: W1 | D26: DATOMS connector | E26: Catalogue sync (hourly): sites, devices, parameters, units | F26: 1. Scheduled job in apps/worker, every hour (and early when the poll sees unknown ids). 2. Read all DATOMS assets (list assets: names, nameplate). Sites, asset types and parameters (name, unit) come in the bulk rows. The live poll (S3-03) upserts them the same way, so the catalogue job spends no bulk credits. 3. Insert new ones, update changed ones in the database. 4. Retire safely (docs/07 section 6): only after a complete walk; only rows missed in 2 consecutive complete walks; retire nothing and alert if more than 5% would go. | G26: Nexus always knows every DATOMS site and device | H26: Data / integration engineer | I26: You (backend) | J26: Innovo: show all DATOMS data | K26: S2-02 | L26: DATOMS sample + field list (Q21, Q22) + read-only key; id stability (Q11) | M26: 2 | N26: Not started | O26: New DATOMS site appears in Nexus within 1 hour
A27: S3-02 | B27: S3 | C27: W1 | D27: DATOMS connector | E27: Auto-link new sites and devices on exact match; others to admin to-do list | F27: 1. When a new DATOMS site appears, link it to a Nexus project if the name matches exactly. 2. Otherwise add it to an 'unlinked' list for admins. 3. Same for devices → assets. | G27: New sites appear automatically, no guessing | H27: Data / integration engineer | I27: You (backend) | J27: Innovo: sites added automatically | K27: S3-01 | M27: 2 | N27: Not started | O27: No guessed links; unmatched items listed
A28: S3-03 | B28: S3 | C28: W1–W2 | D28: DATOMS connector | E28: Live sync (every minute by default): bulk endpoint → packets, latest values, statuses, locations, alerts | F28: 1. Job every 60 s by default (per-type interval, ADR 0006): bulk endpoint only (ADR 0010). Fleet mode when every asset is due, otherwise id mode. In dev, only the configured subset (ADR 0005). 2. Write telemetry.packet (history) and telemetry.latest_packet (current); status, location and alerts on change only. 3. Insert in batches. No per-poll bookkeeping writes (asset_parameter is insert-only; status observed_at only on change). 4. Log how long each run takes and the credits used per window. | G28: Live DATOMS data in Nexus within about 2 poll intervals | H28: Data / integration engineer | I28: You (backend) | J28: Brief: real-time visibility | K28: S3-01 | M28: 2 | N28: Not started | O28: Value in Nexus within 2 poll intervals of DATOMS (N-03)
A29: S3-04 | B29: S3 | C29: W2 | D29: DATOMS connector | E29: History backfill and gap repair after outages (ON HOLD) | F29: 1. On first run, copy all past data from DATOMS (since Jul 2026 for GHAFWOODS). 2. Record the last time synced per device. 3. After an outage, fetch the missing time range. 4. Test by stopping the worker for an hour. | G29: Full history, no gaps after outages | H29: Data / integration engineer | I29: You (backend) | J29: Brief: trends | K29: S3-03 | L29: ON HOLD (decided 2026-10-08). The bulk endpoint has no history (ADR 0010); Nexus builds its own history from polls from day one. Needs a DATOMS history feed (Q12) and a new ADR to use it. Until then, gaps stay gaps and charts show coverage (ADR 0007). | M29: 2 | N29: Blocked | O29: GHAFWOODS history since Jul 2026 loaded; gaps refilled after a forced outage
A30: S3-05 | B30: S3 | C30: W1–W2 | D30: Admin console | E30: Device linking to-do list | F30: 1. Page listing unlinked DATOMS sites/devices (from S4-02). 2. Admin picks the project/asset to link each one to. | G30: Admins link anything not matched automatically | H30: Frontend developer | I30: Colleague (frontend) | J30: Innovo: sites added automatically | K30: S3-02 | M30: 2 | N30: Not started | O30: Admin links an unmatched device to a project
A31: S3-06 | B31: S3 | C31: W2 | D31: Admin console | E31: Integration health page: last sync, errors, delay | F31: 1. Page showing: last successful sync time, number of errors, delay in minutes. 2. Red warning if the sync has stopped. | G31: Admins see if DATOMS data is flowing | H31: Frontend developer | I31: Colleague (frontend) | J31: Risks: DATOMS outage | K31: S3-03 | M31: 1 | N31: Not started | O31: Shows a stopped sync clearly
A32: S3-07 | B32: S3 | C32: W2 | D32: Admin console | E32: Users and roles screen: group-to-role mapping, project assignment | F32: 1. Page listing groups and roles (from S3-09). 2. Assign users to projects. 3. Show each user's role and projects. | G32: Admins manage who sees what | H32: Frontend developer | I32: Colleague (frontend) | J32: Innovo: permissions | K32: S2-06 | M32: 2 | N32: Not started | O32: Admin assigns a user to a project
A33: S4-01 | B33: S4 | C33: W1 | D33: Project page | E33: Chart summaries (5-minute, 1-hour, 1-day) as Nexus rollup tables | F33: 1. Use the rollup functions in db/schema.sql: telemetry.refresh_rollup_5m and refresh_rollup_combine (1 h, 1 day in Asia/Dubai). 2. Worker rollups job (ADR 0007): refresh_rollup_5m once per CLOSED 5-minute bucket, 2 poll intervals after it ends; re-run only for closed buckets that get late packets; 1 h after the hour's last bucket; 1 d after the Dubai day. No sliding window, no in-memory accumulators. 3. Return data coverage (packets / expectedPackets) with each bucket. 4. Check a 30-day query returns in under 1 second. | G33: Fast data for every chart | H33: Data / integration engineer | I33: You (backend) | J33: Brief: trends | K33: S3-03 | M33: 1 | N33: Not started | O33: 30-day chart query under 1 s
A34: S4-02 | B34: S4 | C34: W1 | D34: Project page | E34: Live push: status changes sent to open browsers (Web PubSub) | F34: 1. When the worker sees a status or location change, publish a slim message to Azure Web PubSub (per project group): no parameter values; values.updated hint; summary.updated; chunked well under 1 MB (docs/10, ADR 0008). 2. API gives the browser a Web PubSub token with no group-join rights. POST /v1/live/subscriptions checks permission and scope, then joins the connection to project groups on the server. 3. On any Nexus access change, close the affected live connections so clients re-subscribe through the scope check. Settle with the security-reviewer how the API confirms a connectionId belongs to the caller. | G34: Changes pushed to browsers live | H34: Backend developer | I34: You (backend) | J34: Brief: real-time visibility | K34: S3-03 | M34: 2 | N34: Not started | O34: Pin colour changes without refresh; a user whose project access is removed stops receiving that project's messages at once; nothing project-specific is sent to the portfolio group
A35: S4-03 | B35: S4 | C35: W1–W2 | D35: Project page | E35: Project summary APIs for the equipment and energy info boxes | F35: 1. Endpoints GET /projects/{id}/equipment/summary (Box 2) and GET /projects/{id}/energy/summary (Box 3), as in docs/10. 2. Fill them from the latest DATOMS values: equipment counts from kind = 'physical' assets; energy site totals from site_metric records when DATOMS provides them. Manpower and materials are not built (slots only). | G35: The project page loads its boxes | H35: Backend developer | I35: You (backend) | J35: Sheet: L1 Info boxes | K35: S3-03 | M35: 2 | N35: Not started | O35: The two endpoints return Box 2 and Box 3 as reported; Boxes 1 and 4 are "coming later" slots
A36: S4-04 | B36: S4 | C36: W1 | D36: Project page | E36: Project page layout: site map, side panel, equipment and energy info boxes (space kept for manpower and materials later) | F36: 1. Project page: site map in the centre, equipment and energy info boxes on the right (as structure sheet level 1); leave space for manpower and materials. 2. Load data from S5-03. 3. Back button returns to the portfolio map. | G36: Level 1 project page | H36: Frontend developer | I36: Colleague (frontend) | J36: Sheet: Level 1 | K36: S4-03 | M36: 2 | N36: Not started | O36: Matches structure sheet level 1
A37: S4-05 | B37: S4 | C37: W1–W2 | D37: Project page | E37: Asset pins: icon per type, colour per DATOMS status, clustering, map/satellite switch | F37: 1. Draw one pin per equipment asset (kind = 'physical') at its DATOMS location; no location = "Not on map". 2. Icon by type: tower crane, hoist, equipment, generator; unknown types use the generic icon. 3. Colour by DATOMS status: Running green, Idle amber, Maintenance red, Off grey. 4. Turn on clustering and a Map/Satellite switch. 3D uses the same icons with no callouts or pulse (ADR 0008). | G37: Live equipment pins on the site map | H37: Frontend developer | I37: Colleague (frontend) | J37: Sheet: L1 blinkers on map | K37: S3-03 | L37: Bulk field names for location + status (Q22; DATOMS confirmed the data is in the bulk response); blink vs pulse (Q19) | M37: 2 | N37: Not started | O37: Running green, Idle amber, Maintenance red, Off grey as reported
A38: S4-06 | B38: S4 | C38: W2 | D38: Project page | E38: Live updates on pins and boxes (WebSocket) | F38: 1. Connect to Web PubSub with the token from the API. 2. When a message arrives, update that pin's colour and the info box numbers without reloading. | G38: Map and boxes update live | H38: Frontend developer | I38: Colleague (frontend) | J38: Brief: real-time visibility | K38: S4-02 | M38: 1 | N38: Not started | O38: Update visible within a minute
A39: S4-07 | B39: S4 | C39: W2 | D39: Project page | E39: Asset side panel: live readings, faults, last run | F39: 1. Click a pin = side panel with the asset's latest readings, faults and last run. 2. Link to the equipment detail page. | G39: Asset details on click | H39: Frontend developer | I39: Colleague (frontend) | J39: DATOMS parity | K39: S4-03 | M39: 1 | N39: Not started | O39: Opens on pin click
A40: S5-01 | B40: S5 | C40: W1 | D40: Energy | E40: Energy API: generators, solar, mains, loads by area, site totals and CO2 as reported by DATOMS | F40: 1. Endpoint returning per project: generators (running/total), solar generation, mains, total load, loads by area, site totals and CO2 exactly as DATOMS gives them in the bulk response. Site totals are read from site_metric records (ADR 0009); anything missing shows "no data yet". 2. Compare with the DATOMS Site View for GHAFWOODS; numbers must match. | G40: Energy data for box 3 and the energy page | H40: Backend developer | I40: You (backend) | J40: Brief: energy monitoring; Sheet: L2 Energy | K40: S3-03 | L40: Whether DATOMS has site totals (Q3); bulk field names (Q22) | M40: 3 | N40: Not started | O40: Figures match DATOMS Site View for GHAFWOODS
...

Sheet Architecture
A1: Architecture for a 2-person team (scales without a rewrite)
A3: Layer | B3: Choice | C3: Why | D3: How it scales later
A4: Style | B4: Modular monolith: one API app with modules (Projects, Assets, Telemetry, Materials, Media, Notifications, Access, Admin) + one DATOMS sync worker | C4: Fewest moving parts for 2 people; one deploy, one log, one database | D4: Each module owns its tables, so any module can become its own service
A5: Repo | B5: Monorepo: apps/web, apps/api, apps/worker, packages/shared | C5: Shared TypeScript types between frontend and backend; one CI pipeline | D5: Add apps/bim, apps/reporting later in the same repo
A6: Frontend | B6: React + TypeScript (Vite), Esri ArcGIS Maps SDK for JavaScript (MapView 2D/satellite, SceneView 3D) behind one MapView wrapper, Apache ECharts, MSAL for sign-in | C6: Matches the mockups (Satellite / 2D / 3D); best path to BIM; the wrapper keeps the provider swappable | D6: 3D/BIM viewer added as a new route
A7: Backend API | B7: Node.js + NestJS (TypeScript), OpenAPI contract, typed client generated for the web app | C7: Same language as the frontend, so both of you can read and fix either side | D7: Scale out containers; split modules if needed
A8: Sync worker | B8: Same codebase, separate process: catalogue hourly, live values and notifications every minute (history backfill on hold, see S3-04) | C8: DATOMS is the only source; polling needs no message queue | D8: Add a queue (Service Bus / Event Hubs) only if DATOMS pushes bursts; one worker per new platform
A9: Database | B9: Azure Database for PostgreSQL Flexible Server 16, native partitioning + Nexus rollup tables (5 min / 1 h / 1 day); no TimescaleDB dependency (Azure supports only its Apache edition) | C9: One server to run; charts read automatic 1-min / 1-hour / 1-day summaries | D9: Read replica; move telemetry to its own server or Azure Data Explorer at billions of rows
A10: Latest values | B10: Latest-value table in PostgreSQL, cached in memory per API instance | C10: No Redis to manage in phase 1 | D10: Add Azure Cache for Redis when there are many API instances
A11: Live updates | B11: Azure Web PubSub | C11: Pushes pin and box changes to open browsers; works across many API instances | D11: Already managed and scalable
A12: Files | B12: Azure Blob Storage with short-lived SAS links | C12: Photos, videos, drone files, site plans; never public | D12: Same store for BIM models later
A13: Identity | B13: Microsoft Entra ID; groups mapped to Nexus roles; project scope checked in the API | C13: Employees only; no passwords in Nexus | D13: Same model covers new modules
A14: Hosting | B14: Azure UAE North. Azure Container Apps (API + worker), Azure Static Web Apps (web) | C14: Simpler than Kubernetes; scales automatically | D14: Move to AKS only if ever needed
A15: Operations | B15: Bicep for infrastructure, GitHub Actions or Azure DevOps, Key Vault, Application Insights, dev + prod environments | C15: Rebuild any environment from code; keys never in code | D15: Add a staging environment when the team grows

Sheet Future
A1: Phase 2 and later: what phase 1 already prepares
A3: Feature | B3: Prepared in phase 1 | C3: Work needed later
A4: Tracked materials (structure sheet L2, info box 4) | B4: Space kept on the project page; data model can add a material table | C4: Build once Innovo confirms where materials data comes from (DATOMS sensors or entry in Nexus)
A5: Weather box | B5: Space kept on the project page | C5: Choose a weather source; small API + box
A6: Project gallery, drone library, 2D site plan | B6: Blob storage already in the Azure setup | C6: Media module: uploads, gallery, drone library, site plan overlay
A7: Manpower and HSE (info box 1, LTIFR, safe man-hours) | B7: Generic reading model; space kept on the project page | C7: Build once the source is confirmed (DATOMS, access control or HSE system)
A8: Live CCTV and AI camera events | B8: CCTV permission already in the access model | C8: Build once the video system is named
A9: Project details DATOMS lacks (client, consultant, PM) | B9: Project table has the fields | C9: Admin form, if DATOMS does not hold them
A10: Read-only feed for the reporting app | B10: OpenAPI contract, permissions, audit log | C10: A Reporting module with read-only endpoints and a service account
A11: BIM digital twin | B11: Building / level / zone IDs on every asset; Blob storage | C11: BIM module: Autodesk APS (or IFC viewer) + link model elements to zones and assets. Decide where models are stored
A12: New sensor types | B12: Generic parameter + reading model; catalogue sync picks up new parameters | C12: Nothing for DATOMS sensors; new screens only if wanted
A13: Another data platform | B13: Device has a source-system field; connector layer separate | C13: One new worker writing to the same tables
A14: AI and analytics | B14: All readings kept in PostgreSQL (raw packets + rollups); old partitions can be archived to Blob | C14: Separate Python service reading the telemetry schema
... A17: Many more users and sites | B17: Stateless API, Web PubSub, summaries, load-test harness | C17: Add containers, Redis, read replica as load grows
